<?xml version="1.0" ?>
<!-- =================================================================================== -->
<!-- |    This document was autogenerated by xacro from ur.urdf.xacro                  | -->
<!-- |    EDITING THIS FILE BY HAND IS NOT RECOMMENDED                                 | -->
<!-- =================================================================================== -->
<robot name="poo">
  

  <link name="base">

    <inertial>
      <origin xyz="0 0 0" />
      <mass value="1" />
    </inertial>

    <visual>
      <origin xyz="0 0 0" />
      <geometry>
        <box size=".5 .2 .2" />
      </geometry>
      <material>
        <color rgba="0 1 0 1" />
      </material>
    </visual>

    <visual>
      <origin xyz=".15 0 -.15" rpy="0 0 0" />
      <geometry>
        <sphere radius=".05" />
      </geometry>
      <material>
        <color rgba="0 0 0 1" />
      </material>
    </visual>
    
    <visual>
      <origin xyz="-.15 0 -.15" rpy="0 0 0" />
      <geometry>
        <sphere radius=".05" />
      </geometry>
      <material>
        <color rgba="0 0 0 1" />
      </material>
    </visual>
  </link>

  <link name="pendulum0">
    <inertial>
      <origin xyz="0 0 -.5" rpy="0 0 0" />
      <mass value="1" />
      <inertia ixx="0.001" ixy="0" ixz="0" iyy="0.001" iyz="0" izz="0.001" />
    </inertial>
    <visual>
      <origin xyz="0 0 -.25" rpy="0 0 0" />
      <geometry>
         <cylinder length=".5" radius=".01" />
      </geometry>
      <material>
        <color rgba="1 0 0 1" />
      </material>
    </visual>
    <visual>
      <origin xyz="0 0 -.5" rpy="0 0 0" />
      <geometry>
         <sphere radius=".05" />
      </geometry>
      <material>
        <color rgba="0 0 1 1" />
      </material>
    </visual>
  </link>
  <link name="pendulum1">
    <inertial>
      <origin xyz="0 0 -.5" rpy="0 0 0" />
      <mass value="1" />
      <inertia ixx="0.001" ixy="0" ixz="0" iyy="0.001" iyz="0" izz="0.001" />
    </inertial>
    <visual>
      <origin xyz="0 0 -.25" rpy="0 0 0" />
      <geometry>
         <cylinder length=".5" radius=".01" />
      </geometry>
      <material>
        <color rgba="1 1 0 1" />
      </material>
    </visual>
    <visual>
      <origin xyz="0 0 -.5" rpy="0 0 0" />
      <geometry>
         <sphere radius=".05" />
      </geometry>
      <material>
        <color rgba="0 1 1 1" />
      </material>
    </visual>
  </link>

  <joint name="x" type="prismatic">
    <parent link="world" />
    <child link="base" />
    <axis xyz="1 0 0" />
  </joint>

  <joint name="theta1" type="continuous">
    <parent link="pendulum0" />
    <child link="pendulum1" />
    <axis xyz="0 -1 0" />
    <origin xyz="0 0 -0.5" rpy="0 0 0" />
  </joint>

  <joint name="pendulum_joint" type="continuous">
    <parent link="base" />
    <child link="pendulum0" />
    <axis xyz="0 -1 0" />
    <origin xyz="0 0 0" rpy="0 0 0" />
  </joint>

  <transmission type="SimpleTransmission" name="base_force">
    <actuator name="force" />
    <joint name="x" />
    <mechanicalReduction>1</mechanicalReduction>
  </transmission>

</robot>
</xml>